Workbook

Sheet Raw Data
A1: patient_id | B1: age | C1: gender | D1: hospital | E1: department | F1: diagnosis | G1: insurance_type | H1: admit_date | I1: discharge_date | J1: length_of_stay_days | K1: total_cost_usd | L1: outcome | M1: satisfaction_score
A2: P10000 | B2: 32 | C2: Male | D2: Riverside Medical | E2: Orthopedics | F2: Osteoarthritis | G2: Medicaid | H2: 2022-04-15 | I2: 2022-04-16 | J2: 1 | K2: 4877.43 | L2: Discharged | M2: 3.6
A3: P10001 | B3: 45 | C3: Male | D3: Valley Health | E3: Oncology | F3: Lung Cancer | G3: Uninsured | H3: 2022-07-23 | I3: 2022-07-31 | J3: 8 | K3: 17211.8 | L3: Discharged | M3: 2.3
A4: P10002 | B4: 75 | C4: Female | D4: City General | E4: Orthopedics | F4: Rotator Cuff Tear | G4: Blue Cross | H4: 2022-10-12 | I4: 2022-10-19 | J4: 7 | K4: 12996.21 | L4: Discharged | M4: 3.7
A5: P10003 | B5: 62 | C5: Female | D5: City General | E5: Pulmonology | F5: Pulmonary Embolism | G5: Uninsured | H5: 2022-05-08 | I5: 2022-05-13 | J5: 5 | K5: 8557.64 | L5: Discharged | M5: 3.4
A6: P10004 | B6: 64 | C6: Male | D6: City General | E6: Cardiology | F6: Heart Failure | G6: Blue Cross | H6: 2022-03-23 | I6: 2022-03-30 | J6: 7 | K6: 8608.58 | L6: Discharged | M6: 2.2
A7: P10005 | B7: 38 | C7: Female | D7: Riverside Medical | E7: Orthopedics | F7: Spinal Stenosis | G7: United Health | H7: 2023-12-01 | I7: 2023-12-05 | J7: 4 | K7: 7620.22 | L7: Discharged | M7: 2.8
A8: P10006 | B8: 49 | C8: Male | D8: Northside Clinic | E8: Emergency | F8: Severe Laceration | G8: United Health | H8: 2023-12-06 | I8: 2023-12-07 | J8: 1 | K8: 3259.47 | L8: Readmitted within 30d | M8: 3.8
A9: P10007 | B9: 22 | C9: Female | D9: Northside Clinic | E9: Neurology | F9: Migraine | G9: Medicaid | H9: 2023-08-04 | I9: 2023-08-07 | J9: 3 | K9: 8843.16 | L9: Discharged | M9: 3.2
A10: P10008 | B10: 68 | C10: Female | D10: St. Mary's | E10: Neurology | F10: Epilepsy | G10: Medicaid | H10: 2023-07-29 | I10: 2023-08-01 | J10: 3 | K10: 7453.29 | L10: Discharged | M10: 3.1
A11: P10009 | B11: 35 | C11: Female | D11: City General | E11: Cardiology | F11: Hypertension | G11: Medicaid | H11: 2023-10-05 | I11: 2023-10-08 | J11: 3 | K11: 11076.25 | L11: Discharged | M11: 4.5
A12: P10010 | B12: 67 | C12: Female | D12: Valley Health | E12: Emergency | F12: Severe Laceration | G12: Uninsured | H12: 2022-01-12 | I12: 2022-01-14 | J12: 2 | K12: 3714.11 | L12: Readmitted within 30d | M12: 3.7
A13: P10011 | B13: 61 | C13: Male | D13: Riverside Medical | E13: Emergency | F13: Appendicitis | G13: Aetna | H13: 2022-01-04 | I13: 2022-01-05 | J13: 1 | K13: 4852.66 | L13: Discharged | M13: 3.3
... A23: P10021 | B23: 24 | C23: Male | D23: City General | E23: Orthopedics | F23: Osteoarthritis | G23: Aetna | H23: 2023-05-13 | I23: 2023-05-14 | J23: 1 | K23: 4739.81 | L23: Readmitted within 30d | M23: 3.9
A24: P10022 | B24: 39 | C24: Female | D24: City General | E24: Emergency | F24: Severe Laceration | G24: Aetna | H24: 2022-10-20 | I24: 2022-10-21 | J24: 1 | K24: 4347.62 | L24: Deceased
A25: P10023 | B25: 89 | C25: Female | D25: St. Mary's | E25: Orthopedics | F25: Spinal Stenosis | G25: Medicaid | H25: 2022-03-01 | I25: 2022-03-03 | J25: 2 | K25: 7140.94 | L25: Transferred | M25: 4.6
A26: P10024 | B26: 82 | C26: Male | D26: City General | E26: Oncology | F26: Lung Cancer | G26: Medicaid | H26: 2022-03-12 | I26: 2022-03-21 | J26: 9 | K26: 14879.38 | L26: Discharged | M26: 2.8
A27: P10025 | B27: 33 | C27: Male | D27: Valley Health | E27: Oncology | F27: Lung Cancer | G27: Uninsured | H27: 2022-03-25 | I27: 2022-03-30 | J27: 5 | K27: 18930.23 | L27: Discharged | M27: 4
A28: P10026 | B28: 58 | C28: Male | D28: Riverside Medical | E28: Emergency | F28: Appendicitis | G28: United Health | H28: 2023-10-23 | I28: 2023-10-24 | J28: 1 | K28: 3427.58 | L28: Transferred | M28: 4.3
A29: P10027 | B29: 27 | C29: Male | D29: Northside Clinic | E29: Oncology | F29: Lung Cancer | G29: Medicare | H29: 2023-07-05 | I29: 2023-07-12 | J29: 7 | K29: 20092.34 | L29: Readmitted within 30d | M29: 4.5
A30: P10028 | B30: 65 | C30: Female | D30: St. Mary's | E30: Emergency | F30: Severe Laceration | G30: Uninsured | H30: 2023-11-01 | I30: 2023-11-02 | J30: 1 | K30: 2665.44 | L30: Discharged | M30: 3.6
A31: P10029 | B31: 31 | C31: Male | D31: Riverside Medical | E31: Cardiology | F31: Hypertension | G31: United Health | H31: 2023-07-21 | I31: 2023-07-26 | J31: 5 | K31: 11646.09 | L31: Discharged | M31: 3
A32: P10030 | B32: 51 | C32: Female | D32: Riverside Medical | E32: Cardiology | F32: Hypertension | G32: United Health | H32: 2023-03-10 | I32: 2023-03-17 | J32: 7 | K32: 11544.1 | L32: Discharged | M32: 3.3
A33: P10031 | B33: 34 | C33: Female | D33: St. Mary's | E33: Pulmonology | F33: Pulmonary Embolism | G33: Uninsured | H33: 2023-12-24 | I33: 2023-12-28 | J33: 4 | K33: 7167.3 | L33: Discharged | M33: 4.7
A34: P10032 | B34: 87 | C34: Male | D34: Riverside Medical | E34: Oncology | F34: Breast Cancer | G34: Aetna | H34: 2022-05-11 | I34: 2022-05-17 | J34: 6 | K34: 20159.24 | L34: Readmitted within 30d | M34: 3.7
A35: P10033 | B35: 23 | C35: Female | D35: St. Mary's | E35: Pulmonology | F35: Asthma | G35: United Health | H35: 2022-04-16 | I35: 2022-04-18 | J35: 2 | K35: 7420.7 | L35: Readmitted within 30d | M35: 4.8
A36: P10034 | B36: 48 | C36: Male | D36: St. Mary's | E36: Emergency | F36: Chest Pain | G36: Medicaid | H36: 2022-12-07 | I36: 2022-12-08 | J36: 1 | K36: 3733.23 | L36: Discharged | M36: 3
... A56: P10054 | B56: 28 | C56: Female | D56: City General | E56: Pulmonology | F56: COPD | G56: Blue Cross | H56: 2022-08-18 | I56: 2022-08-21 | J56: 3 | K56: 5574.18 | L56: Discharged | M56: 2.7
A57: P10055 | B57: 21 | C57: Male | D57: St. Mary's | E57: Cardiology | F57: Heart Failure | G57: Medicaid | H57: 2022-05-10 | I57: 2022-05-13 | J57: 3 | K57: 9838.56 | L57: Deceased
A58: P10056 | B58: 77 | C58: Female | D58: Riverside Medical | E58: Orthopedics | F58: Fracture | G58: Medicaid | H58: 2022-11-15 | I58: 2022-11-20 | J58: 5 | K58: 9406.33 | L58: Discharged | M58: 2.8
A59: P10057 | B59: 68 | C59: Male | D59: City General | E59: Oncology | F59: Breast Cancer | G59: Medicare | H59: 2023-12-15 | I59: 2023-12-19 | J59: 4 | K59: 17423.11 | L59: Discharged | M59: 2.2
A60: P10058 | B60: 33 | C60: Male | D60: Riverside Medical | E60: Oncology | F60: Lymphoma | G60: United Health | H60: 2023-01-15 | I60: 2023-01-25 | J60: 10 | K60: 20818.97 | L60: Discharged | M60: 2.6
A61: P10059 | B61: 73 | C61: Female | D61: Northside Clinic | E61: Pulmonology | F61: Asthma | G61: Aetna | H61: 2022-06-30 | I61: 2022-07-06 | J61: 6 | K61: 7609.91 | L61: Discharged | M61: 1.7
A62: P10060 | B62: 86 | C62: Female | D62: Northside Clinic | E62: Emergency | F62: Severe Laceration | G62: Blue Cross | H62: 2022-09-09 | I62: 2022-09-12 | J62: 3 | K62: 4161.8 | L62: Readmitted within 30d | M62: 3.7
A63: P10061 | B63: 66 | C63: Female | D63: City General | E63: Emergency | F63: Severe Laceration | G63: Medicaid | H63: 2023-05-15 | I63: 2023-05-19 | J63: 4 | K63: 5069.81 | L63: Discharged | M63: 4.8
A64: P10062 | B64: 53 | C64: Male | D64: Valley Health | E64: Orthopedics | F64: Fracture | G64: Medicaid | H64: 2023-02-21 | I64: 2023-02-22 | J64: 1 | K64: 7773.98 | L64: Discharged | M64: 3.3
A65: P10063 | B65: 20 | C65: Male | D65: Riverside Medical | E65: Orthopedics | F65: Rotator Cuff Tear | G65: United Health | H65: 2022-09-07 | I65: 2022-09-08 | J65: 1 | K65: 6942.59 | L65: Discharged | M65: 4.6
A66: P10064 | B66: 85 | C66: Female | D66: Northside Clinic | E66: Pulmonology | F66: Pneumonia | G66: Blue Cross | H66: 2023-12-21 | I66: 2023-12-25 | J66: 4 | K66: 7369.75 | L66: Discharged | M66: 3.5
A67: P10065 | B67: 86 | C67: Male | D67: St. Mary's | E67: Orthopedics | F67: Rotator Cuff Tear | G67: Blue Cross | H67: 2023-08-27 | I67: 2023-08-30 | J67: 3 | K67: 10137.25 | L67: Discharged | M67: 3.5
A68: P10066 | B68: 30 | C68: Male | D68: Riverside Medical | E68: Orthopedics | F68: Spinal Stenosis | G68: Medicaid | H68: 2022-11-06 | I68: 2022-11-11 | J68: 5 | K68: 9358.01 | L68: Discharged | M68: 4.4
...

Sheet Dashboard
A1: Hospital Readmissions Dashboard
A2: Interactive summary — filter by hospital using the dropdown below
A4: Filter by Hospital: | B4: All Hospitals
A6: Filter criteria (internal): | B6: =IF($B$4="All Hospitals","*",$B$4) -> *
A8: Total Patients | B8: Avg Length of Stay | C8: Readmission Rate | D8: Avg Satisfaction
A9: =COUNTIFS('Raw Data'!D2:D751,$B$6) -> 750 | B9: =ROUND(AVERAGEIFS('Raw Data'!J2:J751,'Raw Data'!D2:D751,$B$6),1) -> 4.7 | C9: =ROUND(COUNTIFS('Raw Data'!D2:D751,$B$6,'Raw Data'!L2:L751,"Readmitted within 30d")/COUNTIFS('Raw Data'!D2:D751,$B$6)*100,1) -> 19.1 | D9: =ROUND(AVERAGEIFS('Raw Data'!M2:M751,'Raw Data'!D2:D751,$B$6),2) -> 3.55
A11: Readmission Rate by Insurance Type | F11: Cost per Day by Department
A12: Insurance Type | B12: Patients | C12: Readmission Rate | F12: Department | G12: Patients | H12: Avg Cost/Day
A13: Aetna | B13: =COUNTIFS('Raw Data'!D2:D751,$B$6,'Raw Data'!G2:G751,A13) -> 136 | C13: =ROUND(COUNTIFS('Raw Data'!D2:D751,$B$6,'Raw Data'!G2:G751,A13,'Raw Data'!L2:L751,"Readmitted within 30d")/B13*100,1) -> 18.4 | F13: Cardiology | G13: =COUNTIFS('Raw Data'!D2:D751,$B$6,'Raw Data'!E2:E751,F13) -> 118 | H13: =ROUND(SUMPRODUCT((($B$4="All Hospitals")+('Raw Data'!D2:D751=$B$4)>0)*1,('Raw Data'!E2:E751=F13)*1,'Raw Data'!K2:K751/'Raw Data'!J2:J751)/G13,0) -> 3022
A14: Blue Cross | B14: =COUNTIFS('Raw Data'!D2:D751,$B$6,'Raw Data'!G2:G751,A14) -> 128 | C14: =ROUND(COUNTIFS('Raw Data'!D2:D751,$B$6,'Raw Data'!G2:G751,A14,'Raw Data'!L2:L751,"Readmitted within 30d")/B14*100,1) -> 14.8 | F14: Emergency | G14: =COUNTIFS('Raw Data'!D2:D751,$B$6,'Raw Data'!E2:E751,F14) -> 120 | H14: =ROUND(SUMPRODUCT((($B$4="All Hospitals")+('Raw Data'!D2:D751=$B$4)>0)*1,('Raw Data'!E2:E751=F14)*1,'Raw Data'!K2:K751/'Raw Data'!J2:J751)/G14,0) -> 2522
A15: Medicaid | B15: =COUNTIFS('Raw Data'!D2:D751,$B$6,'Raw Data'!G2:G751,A15) -> 118 | C15: =ROUND(COUNTIFS('Raw Data'!D2:D751,$B$6,'Raw Data'!G2:G751,A15,'Raw Data'!L2:L751,"Readmitted within 30d")/B15*100,1) -> 16.1 | F15: Neurology | G15: =COUNTIFS('Raw Data'!D2:D751,$B$6,'Raw Data'!E2:E751,F15) -> 116 | H15: =ROUND(SUMPRODUCT((($B$4="All Hospitals")+('Raw Data'!D2:D751=$B$4)>0)*1,('Raw Data'!E2:E751=F15)*1,'Raw Data'!K2:K751/'Raw Data'!J2:J751)/G15,0) -> 1793
A16: Medicare | B16: =COUNTIFS('Raw Data'!D2:D751,$B$6,'Raw Data'!G2:G751,A16) -> 137 | C16: =ROUND(COUNTIFS('Raw Data'!D2:D751,$B$6,'Raw Data'!G2:G751,A16,'Raw Data'!L2:L751,"Readmitted within 30d")/B16*100,1) -> 17.5 | F16: Oncology | G16: =COUNTIFS('Raw Data'!D2:D751,$B$6,'Raw Data'!E2:E751,F16) -> 124 | H16: =ROUND(SUMPRODUCT((($B$4="All Hospitals")+('Raw Data'!D2:D751=$B$4)>0)*1,('Raw Data'!E2:E751=F16)*1,'Raw Data'!K2:K751/'Raw Data'!J2:J751)/G16,0) -> 2551
A17: Uninsured | B17: =COUNTIFS('Raw Data'!D2:D751,$B$6,'Raw Data'!G2:G751,A17) -> 114 | C17: =ROUND(COUNTIFS('Raw Data'!D2:D751,$B$6,'Raw Data'!G2:G751,A17,'Raw Data'!L2:L751,"Readmitted within 30d")/B17*100,1) -> 27.2 | F17: Orthopedics | G17: =COUNTIFS('Raw Data'!D2:D751,$B$6,'Raw Data'!E2:E751,F17) -> 137 | H17: =ROUND(SUMPRODUCT((($B$4="All Hospitals")+('Raw Data'!D2:D751=$B$4)>0)*1,('Raw Data'!E2:E751=F17)*1,'Raw Data'!K2:K751/'Raw Data'!J2:J751)/G17,0) -> 3229
A18: United Health | B18: =COUNTIFS('Raw Data'!D2:D751,$B$6,'Raw Data'!G2:G751,A18) -> 117 | C18: =ROUND(COUNTIFS('Raw Data'!D2:D751,$B$6,'Raw Data'!G2:G751,A18,'Raw Data'!L2:L751,"Readmitted within 30d")/B18*100,1) -> 21.4 | F18: Pulmonology | G18: =COUNTIFS('Raw Data'!D2:D751,$B$6,'Raw Data'!E2:E751,F18) -> 135 | H18: =ROUND(SUMPRODUCT((($B$4="All Hospitals")+('Raw Data'!D2:D751=$B$4)>0)*1,('Raw Data'!E2:E751=F18)*1,'Raw Data'!K2:K751/'Raw Data'!J2:J751)/G18,0) -> 2039
A21: Readmission Rate by Age Group | F21: Hospital-Level Summary (always all hospitals)
A22: Age Group | B22: Patients | C22: Readmission Rate | F22: Hospital | G22: Avg Cost | H22: Readmit %
A23: 18-30 | B23: =COUNTIFS('Raw Data'!D2:D751,$B$6,'Raw Data'!B2:B751,">="&18,'Raw Data'!B2:B751,"<="&30) -> 131 | C23: =ROUND(COUNTIFS('Raw Data'!D2:D751,$B$6,'Raw Data'!B2:B751,">="&18,'Raw Data'!B2:B751,"<="&30,'Raw Data'!L2:L751,"Readmitted within 30d")/B23*100,1) -> 19.8 | F23: City General | G23: =ROUND(AVERAGEIFS('Raw Data'!K2:K751,'Raw Data'!D2:D751,F23),0) -> 9543 | H23: =ROUND(COUNTIFS('Raw Data'!D2:D751,F23,'Raw Data'!L2:L751,"Readmitted within 30d")/COUNTIFS('Raw Data'!D2:D751,F23)*100,1) -> 13.5
A24: 31-45 | B24: =COUNTIFS('Raw Data'!D2:D751,$B$6,'Raw Data'!B2:B751,">="&31,'Raw Data'!B2:B751,"<="&45) -> 149 | C24: =ROUND(COUNTIFS('Raw Data'!D2:D751,$B$6,'Raw Data'!B2:B751,">="&31,'Raw Data'!B2:B751,"<="&45,'Raw Data'!L2:L751,"Readmitted within 30d")/B24*100,1) -> 18.8 | F24: Northside Clinic | G24: =ROUND(AVERAGEIFS('Raw Data'!K2:K751,'Raw Data'!D2:D751,F24),0) -> 9618 | H24: =ROUND(COUNTIFS('Raw Data'!D2:D751,F24,'Raw Data'!L2:L751,"Readmitted within 30d")/COUNTIFS('Raw Data'!D2:D751,F24)*100,1) -> 23.3
A25: 46-60 | B25: =COUNTIFS('Raw Data'!D2:D751,$B$6,'Raw Data'!B2:B751,">="&46,'Raw Data'!B2:B751,"<="&60) -> 144 | C25: =ROUND(COUNTIFS('Raw Data'!D2:D751,$B$6,'Raw Data'!B2:B751,">="&46,'Raw Data'!B2:B751,"<="&60,'Raw Data'!L2:L751,"Readmitted within 30d")/B25*100,1) -> 18.1 | F25: Riverside Medical | G25: =ROUND(AVERAGEIFS('Raw Data'!K2:K751,'Raw Data'!D2:D751,F25),0) -> 9382 | H25: =ROUND(COUNTIFS('Raw Data'!D2:D751,F25,'Raw Data'!L2:L751,"Readmitted within 30d")/COUNTIFS('Raw Data'!D2:D751,F25)*100,1) -> 18.4
A26: 61-75 | B26: =COUNTIFS('Raw Data'!D2:D751,$B$6,'Raw Data'!B2:B751,">="&61,'Raw Data'!B2:B751,"<="&75) -> 155 | C26: =ROUND(COUNTIFS('Raw Data'!D2:D751,$B$6,'Raw Data'!B2:B751,">="&61,'Raw Data'!B2:B751,"<="&75,'Raw Data'!L2:L751,"Readmitted within 30d")/B26*100,1) -> 14.2 | F26: St. Mary's | G26: =ROUND(AVERAGEIFS('Raw Data'!K2:K751,'Raw Data'!D2:D751,F26),0) -> 9190 | H26: =ROUND(COUNTIFS('Raw Data'!D2:D751,F26,'Raw Data'!L2:L751,"Readmitted within 30d")/COUNTIFS('Raw Data'!D2:D751,F26)*100,1) -> 21.6
A27: 76-90 | B27: =COUNTIFS('Raw Data'!D2:D751,$B$6,'Raw Data'!B2:B751,">="&76,'Raw Data'!B2:B751,"<="&90) -> 171 | C27: =ROUND(COUNTIFS('Raw Data'!D2:D751,$B$6,'Raw Data'!B2:B751,">="&76,'Raw Data'!B2:B751,"<="&90,'Raw Data'!L2:L751,"Readmitted within 30d")/B27*100,1) -> 24 | F27: Valley Health | G27: =ROUND(AVERAGEIFS('Raw Data'!K2:K751,'Raw Data'!D2:D751,F27),0) -> 10106 | H27: =ROUND(COUNTIFS('Raw Data'!D2:D751,F27,'Raw Data'!L2:L751,"Readmitted within 30d")/COUNTIFS('Raw Data'!D2:D751,F27)*100,1) -> 18.2
